Workbook

Sheet Invoices
A1: Invoice No | B1: Vendor | C1: Invoice Date | D1: Amount (INR) | E1: Terms | F1: Due Date | G1: Paid Date | H1: Status | I1: PO Number | J1: Days To Pay
A2: QA-2025-01 | B2: Quartz Analytics | C2: 45931 | D2: 60000 | E2: Net 30 | F2: 45961 | G2: 45962 | H2: Paid | I2: PO-4100 | J2: =IF(G2="","",G2-C2)
A3: CL-2025-01 | B3: Cedar Logistics | C3: 45932 | D3: 40000 | E3: Net 30 | F3: 45962 | G3: 45962 | H3: Paid | I3: PO-4107 | J3: =IF(G3="","",G3-C3)
A4: FM-2025-01 | B4: Falcon Media | C4: 45933 | D4: 80000 | E4: Net 30 | F4: 45963 | G4: 45966 | H4: Paid | I4: PO-4114 | J4: =IF(G4="","",G4-C4)
A5: KF-2025-01 | B5: Kestrel Finance | C5: 45934 | D5: 70000 | E5: Net 30 | F5: 45964 | G5: 45963 | H5: Paid | I5: PO-4121 | J5: =IF(G5="","",G5-C5)
A6: GB-2025-01 | B6: Granite Builders | C6: 45935 | D6: 50000 | E6: Net 30 | F6: 45965 | G6: 45965 | H6: Paid | I6: PO-4128 | J6: =IF(G6="","",G6-C6)
A7: OH-2025-01 | B7: Orchid Hotels | C7: 45936 | D7: 30000 | E7: Net 30 | F7: 45966 | G7: 45961 | H7: Paid | I7: PO-4135 | J7: =IF(G7="","",G7-C7)
A8: LE-2025-01 | B8: Lotus Education | C8: 45937 | D8: 39200 | E8: Net 30 | F8: 45967 | G8: 45962 | H8: Paid | I8: PO-4142 | J8: =IF(G8="","",G8-C8)
A9: ME-2025-01 | B9: Meridian Energy | C9: 45938 | D9: 61500 | E9: Net 30 | F9: 45968 | G9: 45966 | H9: Paid | I9: PO-4149 | J9: =IF(G9="","",G9-C9)
A10: IT-2025-01 | B10: Indigo Textiles | C10: 45939 | D10: 31500 | E10: Net 30 | F10: 45969 | G10: 45969 | H10: Paid | I10: PO-4156 | J10: =IF(G10="","",G10-C10)
A11: HT-2025-01 | B11: Horizon Travel | C11: 45940 | D11: 50000 | E11: Net 30 | F11: 45970 | G11: 45969 | H11: Paid | I11: PO-4163 | J11: =IF(G11="","",G11-C11)
A12: JH-2025-01 | B12: Juniper Health | C12: 45941 | D12: 70000 | E12: Net 30 | F12: 45971 | H12: Overdue | I12: PO-4170 | J12: =IF(G12="","",G12-C12)
A13: SJ-2025-01 | B13: Sapphire Jewels | C13: 45942 | D13: 31500 | E13: Net 30 | F13: 45972 | G13: 45975 | H13: Paid | I13: PO-4177 | J13: =IF(G13="","",G13-C13)
A14: QA-2025-02 | B14: Quartz Analytics | C14: 45961 | D14: 60000 | E14: Net 30 | F14: 45991 | G14: 45994 | H14: Paid | I14: PO-4100 | J14: =IF(G14="","",G14-C14)
A15: CL-2025-02 | B15: Cedar Logistics | C15: 45962 | D15: 41500 | E15: Net 30 | F15: 45992 | G15: 45990 | H15: Paid | I15: PO-4107 | J15: =IF(G15="","",G15-C15)
A16: FM-2025-02 | B16: Falcon Media | C16: 45963 | D16: 80000 | E16: Net 30 | F16: 45993 | G16: 45991 | H16: Paid | I16: PO-4114 | J16: =IF(G16="","",G16-C16)
A17: KF-2025-02 | B17: Kestrel Finance | C17: 45964 | D17: 71500 | E17: Net 30 | F17: 45994 | G17: 45993 | H17: Paid | I17: PO-4121 | J17: =IF(G17="","",G17-C17)
A18: GB-2025-02 | B18: Granite Builders | C18: 45965 | D18: 50000 | E18: Net 30 | F18: 45995 | G18: 45998 | H18: Paid | I18: PO-4128 | J18: =IF(G18="","",G18-C18)
A19: OH-2025-02 | B19: Orchid Hotels | C19: 45966 | D19: 29200 | E19: Net 30 | F19: 45996 | G19: 45995 | H19: Paid | I19: PO-4135 | J19: =IF(G19="","",G19-C19)
A20: LE-2025-02 | B20: Lotus Education | C20: 45967 | D20: 41500 | E20: Net 30 | F20: 45997 | G20: 45998 | H20: Paid | I20: PO-4142 | J20: =IF(G20="","",G20-C20)
A21: ME-2025-02 | B21: Meridian Energy | C21: 45968 | D21: 60000 | E21: Net 30 | F21: 45998 | G21: 45993 | H21: Paid | I21: PO-4149 | J21: =IF(G21="","",G21-C21)
A22: IT-2025-02 | B22: Indigo Textiles | C22: 45969 | D22: 30000 | E22: Net 30 | F22: 45999 | G22: 45997 | H22: Paid | I22: PO-4156 | J22: =IF(G22="","",G22-C22)
A23: HT-2025-02 | B23: Horizon Travel | C23: 45970 | D23: 49200 | E23: Net 30 | F23: 46000 | H23: Overdue | I23: PO-4163 | J23: =IF(G23="","",G23-C23)
A24: JH-2025-02 | B24: Juniper Health | C24: 45971 | D24: 70000 | E24: Net 30 | F24: 46001 | G24: 46000 | H24: Paid | I24: PO-4170 | J24: =IF(G24="","",G24-C24)
A25: SJ-2025-02 | B25: Sapphire Jewels | C25: 45972 | D25: 29200 | E25: Net 30 | F25: 46002 | G25: 46000 | H25: Paid | I25: PO-4177 | J25: =IF(G25="","",G25-C25)
A26: QA-2025-03 | B26: Quartz Analytics | C26: 45991 | D26: 59200 | E26: Net 30 | F26: 46021 | G26: 46024 | H26: Paid | I26: PO-4100 | J26: =IF(G26="","",G26-C26)
A27: CL-2025-03 | B27: Cedar Logistics | C27: 45992 | D27: 40000 | E27: Net 30 | F27: 46022 | G27: 46020 | H27: Paid | I27: PO-4107 | J27: =IF(G27="","",G27-C27)
A28: FM-2025-03 | B28: Falcon Media | C28: 45993 | D28: 80000 | E28: Net 30 | F28: 46023 | G28: 46023 | H28: Paid | I28: PO-4114 | J28: =IF(G28="","",G28-C28)
A29: KF-2025-03 | B29: Kestrel Finance | C29: 45994 | D29: 70000 | E29: Net 30 | F29: 46024 | G29: 46027 | H29: Paid | I29: PO-4121 | J29: =IF(G29="","",G29-C29)
A30: GB-2025-03 | B30: Granite Builders | C30: 45995 | D30: 50000 | E30: Net 30 | F30: 46025 | G30: 46026 | H30: Paid | I30: PO-4128 | J30: =IF(G30="","",G30-C30)
A31: OH-2025-03 | B31: Orchid Hotels | C31: 45996 | D31: 30000 | E31: Net 30 | F31: 46026 | G31: 46027 | H31: Paid | I31: PO-4135 | J31: =IF(G31="","",G31-C31)
A32: LE-2025-03 | B32: Lotus Education | C32: 45997 | D32: 40000 | E32: Net 30 | F32: 46027 | G32: 46022 | H32: Paid | I32: PO-4142 | J32: =IF(G32="","",G32-C32)
A33: ME-2025-03 | B33: Meridian Energy | C33: 45998 | D33: 60000 | E33: Net 30 | F33: 46028 | G33: 46028 | H33: Paid | I33: PO-4149 | J33: =IF(G33="","",G33-C33)
A34: IT-2025-03 | B34: Indigo Textiles | C34: 45999 | D34: 31500 | E34: Net 30 | F34: 46029 | H34: Overdue | I34: PO-4156 | J34: =IF(G34="","",G34-C34)
A35: HT-2025-03 | B35: Horizon Travel | C35: 46000 | D35: 50000 | E35: Net 30 | F35: 46030 | G35: 46033 | H35: Paid | I35: PO-4163 | J35: =IF(G35="","",G35-C35)
A36: JH-2025-03 | B36: Juniper Health | C36: 46001 | D36: 70000 | E36: Net 30 | F36: 46031 | G36: 46034 | H36: Paid | I36: PO-4170 | J36: =IF(G36="","",G36-C36)
A37: SJ-2025-03 | B37: Sapphire Jewels | C37: 46002 | D37: 29200 | E37: Net 30 | F37: 46032 | G37: 46033 | H37: Paid | I37: PO-4177 | J37: =IF(G37="","",G37-C37)
A38: QA-2025-04 | B38: Quartz Analytics | C38: 46021 | D38: 61500 | E38: Net 30 | F38: 46051 | G38: 46046 | H38: Paid | I38: PO-4100 | J38: =IF(G38="","",G38-C38)
A39: CL-2025-04 | B39: Cedar Logistics | C39: 46022 | D39: 39200 | E39: Net 30 | F39: 46052 | G39: 46050 | H39: Paid | I39: PO-4107 | J39: =IF(G39="","",G39-C39)
A40: FM-2026-04 | B40: Falcon Media | C40: 46023 | D40: 80000 | E40: Net 30 | F40: 46053 | G40: 46048 | H40: Paid | I40: PO-4114 | J40: =IF(G40="","",G40-C40)
...

Sheet Summary
A1: Vendor | B1: Total Invoiced (INR) | C1: Open Amount (INR) | D1: Invoices
A2: Nimbus Software | B2: =SUMIF(Invoices!B:B,A2,Invoices!D:D) | C2: =SUMIFS(Invoices!D:D,Invoices!B:B,A2,Invoices!H:H,"Open") | D2: =COUNTIF(Invoices!B:B,A2)
A3: Quartz Analytics | B3: =SUMIF(Invoices!B:B,A3,Invoices!D:D) | C3: =SUMIFS(Invoices!D:D,Invoices!B:B,A3,Invoices!H:H,"Open") | D3: =COUNTIF(Invoices!B:B,A3)
A4: Cedar Logistics | B4: =SUMIF(Invoices!B:B,A4,Invoices!D:D) | C4: =SUMIFS(Invoices!D:D,Invoices!B:B,A4,Invoices!H:H,"Open") | D4: =COUNTIF(Invoices!B:B,A4)
A5: Falcon Media | B5: =SUMIF(Invoices!B:B,A5,Invoices!D:D) | C5: =SUMIFS(Invoices!D:D,Invoices!B:B,A5,Invoices!H:H,"Open") | D5: =COUNTIF(Invoices!B:B,A5)
A6: Kestrel Finance | B6: =SUMIF(Invoices!B:B,A6,Invoices!D:D) | C6: =SUMIFS(Invoices!D:D,Invoices!B:B,A6,Invoices!H:H,"Open") | D6: =COUNTIF(Invoices!B:B,A6)
A7: Granite Builders | B7: =SUMIF(Invoices!B:B,A7,Invoices!D:D) | C7: =SUMIFS(Invoices!D:D,Invoices!B:B,A7,Invoices!H:H,"Open") | D7: =COUNTIF(Invoices!B:B,A7)
A8: Orchid Hotels | B8: =SUMIF(Invoices!B:B,A8,Invoices!D:D) | C8: =SUMIFS(Invoices!D:D,Invoices!B:B,A8,Invoices!H:H,"Open") | D8: =COUNTIF(Invoices!B:B,A8)
A9: Lotus Education | B9: =SUMIF(Invoices!B:B,A9,Invoices!D:D) | C9: =SUMIFS(Invoices!D:D,Invoices!B:B,A9,Invoices!H:H,"Open") | D9: =COUNTIF(Invoices!B:B,A9)
A10: Meridian Energy | B10: =SUMIF(Invoices!B:B,A10,Invoices!D:D) | C10: =SUMIFS(Invoices!D:D,Invoices!B:B,A10,Invoices!H:H,"Open") | D10: =COUNTIF(Invoices!B:B,A10)
A11: Indigo Textiles | B11: =SUMIF(Invoices!B:B,A11,Invoices!D:D) | C11: =SUMIFS(Invoices!D:D,Invoices!B:B,A11,Invoices!H:H,"Open") | D11: =COUNTIF(Invoices!B:B,A11)
A12: Horizon Travel | B12: =SUMIF(Invoices!B:B,A12,Invoices!D:D) | C12: =SUMIFS(Invoices!D:D,Invoices!B:B,A12,Invoices!H:H,"Open") | D12: =COUNTIF(Invoices!B:B,A12)
A13: Juniper Health | B13: =SUMIF(Invoices!B:B,A13,Invoices!D:D) | C13: =SUMIFS(Invoices!D:D,Invoices!B:B,A13,Invoices!H:H,"Open") | D13: =COUNTIF(Invoices!B:B,A13)
A14: Sapphire Jewels | B14: =SUMIF(Invoices!B:B,A14,Invoices!D:D) | C14: =SUMIFS(Invoices!D:D,Invoices!B:B,A14,Invoices!H:H,"Open") | D14: =COUNTIF(Invoices!B:B,A14)
A15: TOTAL | B15: =SUM(B2:B14) | C15: =SUM(C2:C14) | D15: =SUM(D2:D14)

Sheet Adjustments
A1: Ref | B1: Vendor | C1: Note | D1: Amount (INR)
A2: ADJ-01 | B2: Nimbus Software | C2: Q2 invoice NS-2026-02 uplifted 12.5% for 'additional licences' - no change order on file | D2: 37500
A3: ADJ-02 | B3: Nimbus Software | C3: Late-payment interest waived per verbal agreement with vendor; 2% penalty clause not applied | D3: 0
A4: ADJ-03 | B4: Falcon Media | C4: Disputed - awaiting credit note | D4: -80000
